<?xml version='1.0' encoding='utf-8'?>
<robot name="r100-0603">
  <link name="base_link" />
  <joint name="base_link_joint" type="fixed">
    <origin rpy="0 0 0" xyz="0 0 0" />
    <parent link="base_link" />
    <child link="chassis_link" />
  </joint>
  <link name="chassis_link">
    <inertial>
      <origin rpy="1.5707963267948966 0 1.5707963267948966" xyz="0.012 0.002 0.067" />
      <mass value="165.304" />
      <inertia ixx="4.4744" ixy="0.03098" ixz="0.003647" iyy="7.1624" iyz="0.1228" izz="4.6155" />
    </inertial>
  </link>
  <joint name="right_side_cover_link_joint" type="fixed">
    <origin rpy="0 0 0" xyz="0 0 0" />
    <parent link="chassis_link" />
    <child link="right_side_cover_link" />
  </joint>
  <joint name="left_side_cover_link_joint" type="fixed">
    <origin rpy="0 0 0" xyz="0 0 0" />
    <parent link="chassis_link" />
    <child link="left_side_cover_link" />
  </joint>
  <link name="left_side_cover_link">
    </link>
  <link name="right_side_cover_link">
    </link>
  <joint name="front_cover_link_joint" type="fixed">
    <origin rpy="0 0 0" xyz="0 0 0" />
    <parent link="chassis_link" />
    <child link="front_cover_link" />
  </joint>
  <link name="front_cover_link">
    </link>
  <joint name="rear_cover_link_joint" type="fixed">
    <origin rpy="0 0 0" xyz="0 0 0" />
    <parent link="chassis_link" />
    <child link="rear_cover_link" />
  </joint>
  <link name="rear_cover_link">
    </link>
  <joint name="front_lights_link_joint" type="fixed">
    <origin rpy="0 0 0" xyz="0 0 0" />
    <parent link="chassis_link" />
    <child link="front_lights_link" />
  </joint>
  <joint name="rear_lights_link_joint" type="fixed">
    <origin rpy="0 0 0" xyz="0 0 0" />
    <parent link="chassis_link" />
    <child link="rear_lights_link" />
  </joint>
  <link name="front_lights_link">
    </link>
  <link name="rear_lights_link">
    </link>
  <joint name="axle_joint" type="fixed">
    <origin rpy="0 0 0" xyz="0 0 0.05" />
    <parent link="chassis_link" />
    <child link="axle_link" />
  </joint>
  <link name="axle_link">
    </link>
  <joint name="riser_link_joint" type="fixed">
    <origin rpy="0 0 0" xyz="0 0 0.21865" />
    <parent link="chassis_link" />
    <child link="riser_link" />
  </joint>
  <link name="riser_link">
    </link>
  <link name="front_rocker_link">
    <inertial>
      <origin rpy="1.5707963267948966 0 1.5707963267948966" xyz="0 0 0" />
      <mass value="10.267" />
      <inertia ixx="0.0288" ixy="2.20484e-6" ixz="-1.3145e-5" iyy="0.4324" iyz="1.8944e-3" izz="0.4130" />
    </inertial>
  </link>
  <joint name="front_rocker" type="fixed">
    <parent link="axle_link" />
    <child link="front_rocker_link" />
    <origin rpy="0 0 0" xyz="0.319 0 0" />
    <axis xyz="1 0 0" />
    <limit effort="0" lower="-0.08726" upper="0.08726" velocity="0" />
  </joint>
  <link name="front_left_wheel_link">
    <inertial>
      <origin rpy="0 0 0" xyz="0 0 0" />
      <mass value="2.5" />
      <inertia ixx="0.0049007145833333335" ixy="0" ixz="0" iyy="0.0072010124999999986" iyz="0" izz="0.0049007145833333335" />
    </inertial>
  </link>
  <joint name="front_left_wheel_joint" type="continuous">
    <parent link="front_rocker_link" />
    <child link="front_left_wheel_link" />
    <origin rpy="0 0 0" xyz="0 0.27549999999999997 0" />
    <axis xyz="0 1 0" />
    <limit effort="100.0" velocity="10.0" />
  </joint>
  <link name="front_right_wheel_link">
    <inertial>
      <origin rpy="0 0 0" xyz="0 0 0" />
      <mass value="2.5" />
      <inertia ixx="0.0049007145833333335" ixy="0" ixz="0" iyy="0.0072010124999999986" iyz="0" izz="0.0049007145833333335" />
    </inertial>
  </link>
  <joint name="front_right_wheel_joint" type="continuous">
    <parent link="front_rocker_link" />
    <child link="front_right_wheel_link" />
    <origin rpy="0 0 0" xyz="0 -0.27549999999999997 0" />
    <axis xyz="0 1 0" />
    <limit effort="100.0" velocity="10.0" />
  </joint>
  <link name="rear_rocker_link">
    <inertial>
      <origin rpy="1.5707963267948966 0 1.5707963267948966" xyz="0 0 0" />
      <mass value="10.267" />
      <inertia ixx="0.0288" ixy="2.20484e-6" ixz="-1.3145e-5" iyy="0.4324" iyz="1.8944e-3" izz="0.4130" />
    </inertial>
  </link>
  <joint name="rear_rocker" type="fixed">
    <parent link="axle_link" />
    <child link="rear_rocker_link" />
    <origin rpy="0 0 0" xyz="-0.319 0 0" />
    <axis xyz="1 0 0" />
    <limit effort="0" velocity="0" />
  </joint>
  <link name="rear_left_wheel_link">
    <inertial>
      <origin rpy="0 0 0" xyz="0 0 0" />
      <mass value="2.5" />
      <inertia ixx="0.0049007145833333335" ixy="0" ixz="0" iyy="0.0072010124999999986" iyz="0" izz="0.0049007145833333335" />
    </inertial>
  </link>
  <joint name="rear_left_wheel_joint" type="continuous">
    <parent link="rear_rocker_link" />
    <child link="rear_left_wheel_link" />
    <origin rpy="0 0 0" xyz="0 0.27549999999999997 0" />
    <axis xyz="0 1 0" />
    <limit effort="100.0" velocity="10.0" />
  </joint>
  <link name="rear_right_wheel_link">
    <inertial>
      <origin rpy="0 0 0" xyz="0 0 0" />
      <mass value="2.5" />
      <inertia ixx="0.0049007145833333335" ixy="0" ixz="0" iyy="0.0072010124999999986" iyz="0" izz="0.0049007145833333335" />
    </inertial>
  </link>
  <joint name="rear_right_wheel_joint" type="continuous">
    <parent link="rear_rocker_link" />
    <child link="rear_right_wheel_link" />
    <origin rpy="0 0 0" xyz="0 -0.27549999999999997 0" />
    <axis xyz="0 1 0" />
    <limit effort="100.0" velocity="10.0" />
  </joint>
  <link name="imu_0_link">
    <inertial>
      <mass value="0.001" />
      <origin rpy="0 0 0" xyz="0 0 0" />
      <inertia ixx="1e-09" ixy="0.0" ixz="0.0" iyy="1e-09" iyz="0.0" izz="1e-09" />
    </inertial>
  </link>
  <joint name="imu_0_joint" type="fixed">
    <parent link="chassis_link" />
    <child link="imu_0_link" />
    <origin rpy="0 0 0" xyz="0.2085 -0.2902 0.1681" />
  </joint>
  <link name="default_mount" />
  <joint name="default_mount_joint" type="fixed">
    <parent link="riser_link" />
    <child link="default_mount" />
    <origin rpy="0 0 0" xyz="0 0 0.06135" />
  </joint>
  <link name="lift_0_mount_rotated_link" />
  <joint name="lift_0_mount_rotated_joint" type="fixed">
    <parent link="lift_0_mount" />
    <child link="lift_0_mount_rotated_link" />
    <origin rpy="0.0 0.0 -0.7854" xyz="0.0 0.0 0.0" />
  </joint>
  <link name="arm_mount_left_link" />
  <joint name="arm_mount_left_joint" type="fixed">
    <parent link="lift_0_mount_rotated_link" />
    <child link="arm_mount_left_link" />
    <origin rpy="-1.0389 0.1675 -0.6876" xyz="0.1452 0.0611 -0.5157" />
  </joint>
  <link name="arm_mount_right_link" />
  <joint name="arm_mount_right_joint" type="fixed">
    <parent link="lift_0_mount_rotated_link" />
    <child link="arm_mount_right_link" />
    <origin rpy="1.0389 0.1675 0.6876" xyz="0.1452 -0.0611 -0.5157" />
  </joint>
  <link name="lidar2d_0_link">
    </link>
  <link name="lidar2d_0_laser">
    <inertial>
      <mass value="1.1" />
      <origin xyz="0 0 0" />
      <inertia ixx="0.00307156543804" ixy="0.0" ixz="0.0" iyy="0.0031284904152700005" iyz="0.0" izz="0.00196432421427" />
    </inertial>
  </link>
  <joint name="lidar2d_0_joint" type="fixed">
    <origin rpy="0.0 0.0 0.0" xyz="0.3922 0.0 0.1856" />
    <parent link="chassis_link" />
    <child link="lidar2d_0_link" />
  </joint>
  <joint name="lidar2d_0_laser_joint" type="fixed">
    <origin rpy="0 0 0" xyz="0 0 0.0474" />
    <parent link="lidar2d_0_link" />
    <child link="lidar2d_0_laser" />
  </joint>
  <link name="lidar2d_1_link">
    </link>
  <link name="lidar2d_1_laser">
    <inertial>
      <mass value="1.1" />
      <origin xyz="0 0 0" />
      <inertia ixx="0.00307156543804" ixy="0.0" ixz="0.0" iyy="0.0031284904152700005" iyz="0.0" izz="0.00196432421427" />
    </inertial>
  </link>
  <joint name="lidar2d_1_joint" type="fixed">
    <origin rpy="0.0 0.0 3.14159" xyz="-0.3922 0.0 0.1856" />
    <parent link="chassis_link" />
    <child link="lidar2d_1_link" />
  </joint>
  <joint name="lidar2d_1_laser_joint" type="fixed">
    <origin rpy="0 0 0" xyz="0 0 0.0474" />
    <parent link="lidar2d_1_link" />
    <child link="lidar2d_1_laser" />
  </joint>
  <link name="imu_1_base_link" />
  <link name="imu_1_link">
    </link>
  <joint name="imu_1_base_joint" type="fixed">
    <origin rpy="0.0 0.0 3.14" xyz="0.0 -0.136 0.0" />
    <parent link="default_mount" />
    <child link="imu_1_base_link" />
  </joint>
  <joint name="imu_1_joint" type="fixed">
    <origin xyz="0 0 0.0025" />
    <parent link="imu_1_base_link" />
    <child link="imu_1_link" />
  </joint>
  <link name="lift_0_plate_link">
    <inertial>
      <mass value="1.0" />
      <origin rpy="0.0 0.0 0.0" xyz="0.0 0.0 0.01" />
      <inertia ixx="0.003366666666666667" ixy="0.0" ixz="0.0" iyy="0.003366666666666667" iyz="0.0" izz="0.006666666666666668" />
    </inertial>
  </link>
  <joint name="lift_0_plate_joint" type="fixed">
    <child link="lift_0_plate_link" />
    <parent link="default_mount" />
    <origin rpy="0.0 0.0 0.785398" xyz="0.1115 0.0 -0.0037" />
  </joint>
  <joint name="lift_0_base_joint" type="fixed">
    <child link="lift_0_base_link" />
    <parent link="lift_0_plate_link" />
    <origin rpy="0.0 0.0 0.0" xyz="0.0 0.0 0.018000000000000002" />
  </joint>
  <link name="lift_0_base_link">
    <inertial>
      <mass value="10.0" />
      <origin rpy="0.0 0.0 0.0" xyz="0.0 0.0 0.41035" />
      <inertia ixx="0.5838132083333333" ixy="0.0" ixz="0.0" iyy="0.5838132083333333" iyz="0.0" izz="0.0450456" />
    </inertial>
  </link>
  <link name="lift_0_lower_link">
    <inertial>
      <mass value="10.0" />
      <origin rpy="0.0 0.0 0.0" xyz="0.0 0.0 0.3999999999999999" />
      <inertia ixx="0.5536393416666664" ixy="0.0" ixz="0.0" iyy="0.5537174666666664" iyz="0.0" izz="0.040690141666666665" />
    </inertial>
  </link>
  <joint name="lift_0_lower_joint" type="prismatic">
    <child link="lift_0_lower_link" />
    <parent link="lift_0_base_link" />
    <origin rpy="0.0 0.0 0.0" xyz="0.0 0.0 0.027" />
    <limit effort="2000" lower="0.0" upper="0.4" velocity="0.088" />
    <axis xyz="0 0 1" />
    <dynamics damping="0.01" friction="0.01" />
  </joint>
  <link name="lift_0_upper_link">
    <inertial>
      <mass value="10.0" />
      <origin rpy="0.0 0.0 0.0" xyz="0.0 0.0 0.41900000000000004" />
      <inertia ixx="0.5990708333333334" ixy="0.0" ixz="0.0" iyy="0.5990708333333334" iyz="0.0" izz="0.027735" />
    </inertial>
  </link>
  <joint name="lift_0_upper_joint" type="prismatic">
    <child link="lift_0_upper_link" />
    <parent link="lift_0_lower_link" />
    <origin rpy="0.0 0.0 0.0" xyz="0.0 0.0 0.007" />
    <axis xyz="0 0 1" />
    <limit effort="2000" lower="0.0" upper="0.4" velocity="0.088" />
    <dynamics damping="0.01" friction="0.01" />
  </joint>
  <link name="lift_0_mount" />
  <joint name="lift_0_mount_joint" type="fixed">
    <child link="lift_0_mount" />
    <parent link="lift_0_upper_link" />
    <origin rpy="0.0 0.0 0.0" xyz="0.0 0.0 0.8380000000000001" />
  </joint>
  <joint name="arm_0_fr3_joint0" type="fixed">
    <child link="arm_0_fr3_link0" />
    <parent link="arm_mount_left_link" />
    <origin rpy="0.0 0.0 0.0" xyz="0.0 0.0 0.0" />
  </joint>
  <link name="arm_0_fr3_link0">
    <inertial>
      <origin rpy="0 0 0" xyz="-0.0172 0.0004 0.0745" />
      <mass value="2.3966" />
      <inertia ixx="0.009" ixy="0.0" ixz="0.002" iyy="0.0115" iyz="0.0" izz="0.0085" />
    </inertial>
  </link>
  <link name="arm_0_fr3_link1">
    <inertial>
      <origin rpy="0 0 0" xyz="0.0000004128 -0.0181251324 -0.0386035970" />
      <mass value="2.9274653454" />
      <inertia ixx="0.023927316485107913" ixy="1.3317903455714081e-05" ixz="-0.00011404774918616684" iyy="0.0224821613275756" iyz="-0.0019950320628240115" izz="0.006350098258530016" />
    </inertial>
  </link>
  <joint name="arm_0_fr3_joint1" type="revolute">
    <origin rpy="0 0 0" xyz="0 0 0.333" />
    <parent link="arm_0_fr3_link0" />
    <child link="arm_0_fr3_link1" />
    <axis xyz="0 0 1" />
    <limit effort="87.0" lower="-2.9007" upper="2.9007" velocity="2.62" />
    <safety_controller k_position="100.0" k_velocity="40.0" soft_lower_limit="-2.9007" soft_upper_limit="2.9007" />
    <position_based_velocity_limits deceleration_limit="6.0" velocity_offset="0.652" />
    <dynamics D="1" K="7000" damping="0.003" friction="0.2" mu_coulomb="0" mu_viscous="16" />
  </joint>
  <link name="arm_0_fr3_link2">
    <inertial>
      <origin rpy="0 0 0" xyz="0.0031828864 -0.0743221644 0.0088146084" />
      <mass value="2.9355370338" />
      <inertia ixx="0.041938946257609425" ixy="0.00020257331521090626" ixz="0.004077784227179924" iyy="0.02514514885014724" iyz="-0.0042252158006570156" izz="0.06170214472888839" />
    </inertial>
  </link>
  <joint name="arm_0_fr3_joint2" type="revolute">
    <origin rpy="-1.570796326794897 0 0" xyz="0 0 0" />
    <parent link="arm_0_fr3_link1" />
    <child link="arm_0_fr3_link2" />
    <axis xyz="0 0 1" />
    <limit effort="87.0" lower="-1.8361" upper="1.8361" velocity="2.62" />
    <safety_controller k_position="100.0" k_velocity="40.0" soft_lower_limit="-1.8361" soft_upper_limit="1.8361" />
    <position_based_velocity_limits deceleration_limit="2.585" velocity_offset="0.25" />
    <dynamics D="1" K="7000" damping="0.003" friction="0.2" mu_coulomb="0" mu_viscous="16" />
  </joint>
  <link name="arm_0_fr3_link3">
    <inertial>
      <origin rpy="0 0 0" xyz="0.0407015686 -0.0048200565 -0.0289730823" />
      <mass value="2.2449013699" />
      <inertia ixx="0.02410142547240885" ixy="0.002404694559042109" ixz="-0.002856269270114313" iyy="0.01974053266708178" iyz="-0.002104212683891874" izz="0.019044494482244823" />
    </inertial>
  </link>
  <joint name="arm_0_fr3_joint3" type="revolute">
    <origin rpy="1.570796326794897 0 0" xyz="0 -0.316 0" />
    <parent link="arm_0_fr3_link2" />
    <child link="arm_0_fr3_link3" />
    <axis xyz="0 0 1" />
    <limit effort="87.0" lower="-2.9007" upper="2.9007" velocity="2.62" />
    <safety_controller k_position="100.0" k_velocity="40.0" soft_lower_limit="-2.9007" soft_upper_limit="2.9007" />
    <position_based_velocity_limits deceleration_limit="3.5" velocity_offset="0.2005" />
    <dynamics D="1" K="7000" damping="0.003" friction="0.2" mu_coulomb="0" mu_viscous="16" />
  </joint>
  <link name="arm_0_fr3_link4">
    <inertial>
      <origin rpy="0 0 0" xyz="-0.0459100965 0.0630492960 -0.0085187868" />
      <mass value="2.6155955791" />
      <inertia ixx="0.03452998321913202" ixy="0.01322552265982813" ixz="0.01015142998484113" iyy="0.028881621933049058" iyz="-0.0009762833870704552" izz="0.04125471171146641" />
    </inertial>
  </link>
  <joint name="arm_0_fr3_joint4" type="revolute">
    <origin rpy="1.570796326794897 0 0" xyz="0.0825 0 0" />
    <parent link="arm_0_fr3_link3" />
    <child link="arm_0_fr3_link4" />
    <axis xyz="0 0 1" />
    <limit effort="87.0" lower="-3.077" upper="-0.1169" velocity="2.62" />
    <safety_controller k_position="100.0" k_velocity="40.0" soft_lower_limit="-3.077" soft_upper_limit="-0.1169" />
    <position_based_velocity_limits deceleration_limit="4.0" velocity_offset="0.3542" />
    <dynamics D="1" K="7000" damping="0.003" friction="0.2" mu_coulomb="0" mu_viscous="16" />
  </joint>
  <link name="arm_0_fr3_link5">
    <inertial>
      <origin rpy="0 0 0" xyz="-0.0016039605 0.0292536262 -0.0972965990" />
      <mass value="2.3271207594" />
      <inertia ixx="0.051610278463662895" ixy="-0.005715173387783472" ixz="-0.0035673167625872135" iyy="0.04787729713371481" iyz="0.010673985108535986" izz="0.016423625579357254" />
    </inertial>
  </link>
  <joint name="arm_0_fr3_joint5" type="revolute">
    <origin rpy="-1.570796326794897 0 0" xyz="-0.0825 0.384 0" />
    <parent link="arm_0_fr3_link4" />
    <child link="arm_0_fr3_link5" />
    <axis xyz="0 0 1" />
    <limit effort="12.0" lower="-2.8763" upper="2.8763" velocity="5.26" />
    <safety_controller k_position="100.0" k_velocity="40.0" soft_lower_limit="-2.8763" soft_upper_limit="2.8763" />
    <position_based_velocity_limits deceleration_limit="17.0" velocity_offset="0.5738" />
    <dynamics D="1" K="7000" damping="0.003" friction="0.2" mu_coulomb="0" mu_viscous="16" />
  </joint>
  <link name="arm_0_fr3_link6">
    <inertial>
      <origin rpy="0 0 0" xyz="0.0597131221 -0.0410294666 -0.0101692726" />
      <mass value="1.8170376524" />
      <inertia ixx="0.005412333594383447" ixy="0.006193456360285834" ixz="0.0014219289306117652" iyy="0.014058329545509979" iyz="-0.0013140753741120031" izz="0.016080817924212554" />
    </inertial>
  </link>
  <joint name="arm_0_fr3_joint6" type="revolute">
    <origin rpy="1.570796326794897 0 0" xyz="0 0 0" />
    <parent link="arm_0_fr3_link5" />
    <child link="arm_0_fr3_link6" />
    <axis xyz="0 0 1" />
    <limit effort="12.0" lower="0.4398" upper="4.6216" velocity="4.18" />
    <safety_controller k_position="100.0" k_velocity="40.0" soft_lower_limit="0.4398" soft_upper_limit="4.6216" />
    <position_based_velocity_limits deceleration_limit="5.5" velocity_offset="0.4885" />
    <dynamics D="1" K="7000" damping="0.003" friction="0.2" mu_coulomb="0" mu_viscous="16" />
  </joint>
  <link name="arm_0_fr3_link7">
    <inertial>
      <origin rpy="0 0 0" xyz="0.0045225817 0.0086261921 -0.0161633251" />
      <mass value="0.6271432862" />
      <inertia ixx="0.00021092389150104718" ixy="-2.433299114461931e-05" ixz="4.564480393778983e-05" iyy="0.00017718568002411474" iyz="8.744070223226438e-05" izz="5.993190599659971e-05" />
    </inertial>
  </link>
  <joint name="arm_0_fr3_joint7" type="revolute">
    <origin rpy="1.570796326794897 0 0" xyz="0.088 0 0" />
    <parent link="arm_0_fr3_link6" />
    <child link="arm_0_fr3_link7" />
    <axis xyz="0 0 1" />
    <limit effort="12.0" lower="-3.0508" upper="3.0508" velocity="5.26" />
    <safety_controller k_position="100.0" k_velocity="40.0" soft_lower_limit="-3.0508" soft_upper_limit="3.0508" />
    <position_based_velocity_limits deceleration_limit="17.0" velocity_offset="0.4592" />
    <dynamics D="1" K="7000" damping="0.003" friction="0.2" mu_coulomb="0" mu_viscous="16" />
  </joint>
  <link name="arm_0_fr3_link8" />
  <joint name="arm_0_fr3_joint8" type="fixed">
    <origin rpy="0 0 0" xyz="0 0 0.107" />
    <parent link="arm_0_fr3_link7" />
    <child link="arm_0_fr3_link8" />
  </joint>
  <joint name="arm_1_fr3_joint0" type="fixed">
    <child link="arm_1_fr3_link0" />
    <parent link="arm_mount_right_link" />
    <origin rpy="0.0 0.0 0.0" xyz="0.0 0.0 0.0" />
  </joint>
  <link name="arm_1_fr3_link0">
    <inertial>
      <origin rpy="0 0 0" xyz="-0.0172 0.0004 0.0745" />
      <mass value="2.3966" />
      <inertia ixx="0.009" ixy="0.0" ixz="0.002" iyy="0.0115" iyz="0.0" izz="0.0085" />
    </inertial>
  </link>
  <link name="arm_1_fr3_link1">
    <inertial>
      <origin rpy="0 0 0" xyz="0.0000004128 -0.0181251324 -0.0386035970" />
      <mass value="2.9274653454" />
      <inertia ixx="0.023927316485107913" ixy="1.3317903455714081e-05" ixz="-0.00011404774918616684" iyy="0.0224821613275756" iyz="-0.0019950320628240115" izz="0.006350098258530016" />
    </inertial>
  </link>
  <joint name="arm_1_fr3_joint1" type="revolute">
    <origin rpy="0 0 0" xyz="0 0 0.333" />
    <parent link="arm_1_fr3_link0" />
    <child link="arm_1_fr3_link1" />
    <axis xyz="0 0 1" />
    <limit effort="87.0" lower="-2.9007" upper="2.9007" velocity="2.62" />
    <safety_controller k_position="100.0" k_velocity="40.0" soft_lower_limit="-2.9007" soft_upper_limit="2.9007" />
    <position_based_velocity_limits deceleration_limit="6.0" velocity_offset="0.652" />
    <dynamics D="1" K="7000" damping="0.003" friction="0.2" mu_coulomb="0" mu_viscous="16" />
  </joint>
  <link name="arm_1_fr3_link2">
    <inertial>
      <origin rpy="0 0 0" xyz="0.0031828864 -0.0743221644 0.0088146084" />
      <mass value="2.9355370338" />
      <inertia ixx="0.041938946257609425" ixy="0.00020257331521090626" ixz="0.004077784227179924" iyy="0.02514514885014724" iyz="-0.0042252158006570156" izz="0.06170214472888839" />
    </inertial>
  </link>
  <joint name="arm_1_fr3_joint2" type="revolute">
    <origin rpy="-1.570796326794897 0 0" xyz="0 0 0" />
    <parent link="arm_1_fr3_link1" />
    <child link="arm_1_fr3_link2" />
    <axis xyz="0 0 1" />
    <limit effort="87.0" lower="-1.8361" upper="1.8361" velocity="2.62" />
    <safety_controller k_position="100.0" k_velocity="40.0" soft_lower_limit="-1.8361" soft_upper_limit="1.8361" />
    <position_based_velocity_limits deceleration_limit="2.585" velocity_offset="0.25" />
    <dynamics D="1" K="7000" damping="0.003" friction="0.2" mu_coulomb="0" mu_viscous="16" />
  </joint>
  <link name="arm_1_fr3_link3">
    <inertial>
      <origin rpy="0 0 0" xyz="0.0407015686 -0.0048200565 -0.0289730823" />
      <mass value="2.2449013699" />
      <inertia ixx="0.02410142547240885" ixy="0.002404694559042109" ixz="-0.002856269270114313" iyy="0.01974053266708178" iyz="-0.002104212683891874" izz="0.019044494482244823" />
    </inertial>
  </link>
  <joint name="arm_1_fr3_joint3" type="revolute">
    <origin rpy="1.570796326794897 0 0" xyz="0 -0.316 0" />
    <parent link="arm_1_fr3_link2" />
    <child link="arm_1_fr3_link3" />
    <axis xyz="0 0 1" />
    <limit effort="87.0" lower="-2.9007" upper="2.9007" velocity="2.62" />
    <safety_controller k_position="100.0" k_velocity="40.0" soft_lower_limit="-2.9007" soft_upper_limit="2.9007" />
    <position_based_velocity_limits deceleration_limit="3.5" velocity_offset="0.2005" />
    <dynamics D="1" K="7000" damping="0.003" friction="0.2" mu_coulomb="0" mu_viscous="16" />
  </joint>
  <link name="arm_1_fr3_link4">
    <inertial>
      <origin rpy="0 0 0" xyz="-0.0459100965 0.0630492960 -0.0085187868" />
      <mass value="2.6155955791" />
      <inertia ixx="0.03452998321913202" ixy="0.01322552265982813" ixz="0.01015142998484113" iyy="0.028881621933049058" iyz="-0.0009762833870704552" izz="0.04125471171146641" />
    </inertial>
  </link>
  <joint name="arm_1_fr3_joint4" type="revolute">
    <origin rpy="1.570796326794897 0 0" xyz="0.0825 0 0" />
    <parent link="arm_1_fr3_link3" />
    <child link="arm_1_fr3_link4" />
    <axis xyz="0 0 1" />
    <limit effort="87.0" lower="-3.077" upper="-0.1169" velocity="2.62" />
    <safety_controller k_position="100.0" k_velocity="40.0" soft_lower_limit="-3.077" soft_upper_limit="-0.1169" />
    <position_based_velocity_limits deceleration_limit="4.0" velocity_offset="0.3542" />
    <dynamics D="1" K="7000" damping="0.003" friction="0.2" mu_coulomb="0" mu_viscous="16" />
  </joint>
  <link name="arm_1_fr3_link5">
    <inertial>
      <origin rpy="0 0 0" xyz="-0.0016039605 0.0292536262 -0.0972965990" />
      <mass value="2.3271207594" />
      <inertia ixx="0.051610278463662895" ixy="-0.005715173387783472" ixz="-0.0035673167625872135" iyy="0.04787729713371481" iyz="0.010673985108535986" izz="0.016423625579357254" />
    </inertial>
  </link>
  <joint name="arm_1_fr3_joint5" type="revolute">
    <origin rpy="-1.570796326794897 0 0" xyz="-0.0825 0.384 0" />
    <parent link="arm_1_fr3_link4" />
    <child link="arm_1_fr3_link5" />
    <axis xyz="0 0 1" />
    <limit effort="12.0" lower="-2.8763" upper="2.8763" velocity="5.26" />
    <safety_controller k_position="100.0" k_velocity="40.0" soft_lower_limit="-2.8763" soft_upper_limit="2.8763" />
    <position_based_velocity_limits deceleration_limit="17.0" velocity_offset="0.5738" />
    <dynamics D="1" K="7000" damping="0.003" friction="0.2" mu_coulomb="0" mu_viscous="16" />
  </joint>
  <link name="arm_1_fr3_link6">
    <inertial>
      <origin rpy="0 0 0" xyz="0.0597131221 -0.0410294666 -0.0101692726" />
      <mass value="1.8170376524" />
      <inertia ixx="0.005412333594383447" ixy="0.006193456360285834" ixz="0.0014219289306117652" iyy="0.014058329545509979" iyz="-0.0013140753741120031" izz="0.016080817924212554" />
    </inertial>
  </link>
  <joint name="arm_1_fr3_joint6" type="revolute">
    <origin rpy="1.570796326794897 0 0" xyz="0 0 0" />
    <parent link="arm_1_fr3_link5" />
    <child link="arm_1_fr3_link6" />
    <axis xyz="0 0 1" />
    <limit effort="12.0" lower="0.4398" upper="4.6216" velocity="4.18" />
    <safety_controller k_position="100.0" k_velocity="40.0" soft_lower_limit="0.4398" soft_upper_limit="4.6216" />
    <position_based_velocity_limits deceleration_limit="5.5" velocity_offset="0.4885" />
    <dynamics D="1" K="7000" damping="0.003" friction="0.2" mu_coulomb="0" mu_viscous="16" />
  </joint>
  <link name="arm_1_fr3_link7">
    <inertial>
      <origin rpy="0 0 0" xyz="0.0045225817 0.0086261921 -0.0161633251" />
      <mass value="0.6271432862" />
      <inertia ixx="0.00021092389150104718" ixy="-2.433299114461931e-05" ixz="4.564480393778983e-05" iyy="0.00017718568002411474" iyz="8.744070223226438e-05" izz="5.993190599659971e-05" />
    </inertial>
  </link>
  <joint name="arm_1_fr3_joint7" type="revolute">
    <origin rpy="1.570796326794897 0 0" xyz="0.088 0 0" />
    <parent link="arm_1_fr3_link6" />
    <child link="arm_1_fr3_link7" />
    <axis xyz="0 0 1" />
    <limit effort="12.0" lower="-3.0508" upper="3.0508" velocity="5.26" />
    <safety_controller k_position="100.0" k_velocity="40.0" soft_lower_limit="-3.0508" soft_upper_limit="3.0508" />
    <position_based_velocity_limits deceleration_limit="17.0" velocity_offset="0.4592" />
    <dynamics D="1" K="7000" damping="0.003" friction="0.2" mu_coulomb="0" mu_viscous="16" />
  </joint>
  <link name="arm_1_fr3_link8" />
  <joint name="arm_1_fr3_joint8" type="fixed">
    <origin rpy="0 0 0" xyz="0 0 0.107" />
    <parent link="arm_1_fr3_link7" />
    <child link="arm_1_fr3_link8" />
  </joint>
  <joint name="arm_0_gripper_fr3_hand_joint" type="fixed">
    <parent link="arm_0_fr3_link8" />
    <child link="arm_0_gripper_fr3_hand" />
    <origin rpy="0 0 -0.7853981633974483" xyz="0 0 0" />
  </joint>
  <link name="arm_0_gripper_fr3_hand">
    <inertial>
      <origin rpy="0 0 0" xyz="-0.0000376 0.0119128 0.0207260" />
      <mass value="0.6544" />
      <inertia ixx="0.00186" ixy="0.0" ixz="0.0" iyy="0.0003" iyz="-2e-05" izz="0.00174" />
    </inertial>
  </link>
  <link name="arm_0_gripper_fr3_hand_tcp" />
  <joint name="arm_0_gripper_fr3_hand_tcp_joint" type="fixed">
    <origin rpy="0 0 0" xyz="0 0 0.1034" />
    <parent link="arm_0_gripper_fr3_hand" />
    <child link="arm_0_gripper_fr3_hand_tcp" />
  </joint>
  <link name="arm_0_gripper_fr3_leftfinger">
    <inertial>
      <origin rpy="0 0 0" xyz="0 0.0152850 0.0219675" />
      <mass value="0.0291" />
      <inertia ixx="8.49e-06" ixy="0.0" ixz="0.0" iyy="8.53e-06" iyz="-1.06e-06" izz="1.77e-06" />
    </inertial>
  </link>
  <link name="arm_0_gripper_fr3_rightfinger">
    <inertial>
      <origin rpy="0 0 0" xyz="0 0.0152850 0.0219675" />
      <mass value="0.0291" />
      <inertia ixx="8.49e-06" ixy="0.0" ixz="0.0" iyy="8.53e-06" iyz="-1.06e-06" izz="1.77e-06" />
    </inertial>
  </link>
  <joint name="arm_0_gripper_fr3_finger_joint1" type="prismatic">
    <parent link="arm_0_gripper_fr3_hand" />
    <child link="arm_0_gripper_fr3_leftfinger" />
    <origin rpy="0 0 0" xyz="0 0 0.0584" />
    <axis xyz="0 1 0" />
    <limit effort="100" lower="0.0" upper="0.04" velocity="0.2" />
    <dynamics damping="0.3" />
  </joint>
  <joint name="arm_0_gripper_fr3_finger_joint2" type="prismatic">
    <parent link="arm_0_gripper_fr3_hand" />
    <child link="arm_0_gripper_fr3_rightfinger" />
    <origin rpy="0 0 3.141592653589793" xyz="0 0 0.0584" />
    <axis xyz="0 1 0" />
    <limit effort="100" lower="0.0" upper="0.04" velocity="0.2" />
    <dynamics damping="0.3" />
  </joint>
  <joint name="arm_1_gripper_fr3_hand_joint" type="fixed">
    <parent link="arm_1_fr3_link8" />
    <child link="arm_1_gripper_fr3_hand" />
    <origin rpy="0 0 -0.7853981633974483" xyz="0 0 0" />
  </joint>
  <link name="arm_1_gripper_fr3_hand">
    <inertial>
      <origin rpy="0 0 0" xyz="-0.0000376 0.0119128 0.0207260" />
      <mass value="0.6544" />
      <inertia ixx="0.00186" ixy="0.0" ixz="0.0" iyy="0.0003" iyz="-2e-05" izz="0.00174" />
    </inertial>
  </link>
  <link name="arm_1_gripper_fr3_hand_tcp" />
  <joint name="arm_1_gripper_fr3_hand_tcp_joint" type="fixed">
    <origin rpy="0 0 0" xyz="0 0 0.1034" />
    <parent link="arm_1_gripper_fr3_hand" />
    <child link="arm_1_gripper_fr3_hand_tcp" />
  </joint>
  <link name="arm_1_gripper_fr3_leftfinger">
    <inertial>
      <origin rpy="0 0 0" xyz="0 0.0152850 0.0219675" />
      <mass value="0.0291" />
      <inertia ixx="8.49e-06" ixy="0.0" ixz="0.0" iyy="8.53e-06" iyz="-1.06e-06" izz="1.77e-06" />
    </inertial>
  </link>
  <link name="arm_1_gripper_fr3_rightfinger">
    <inertial>
      <origin rpy="0 0 0" xyz="0 0.0152850 0.0219675" />
      <mass value="0.0291" />
      <inertia ixx="8.49e-06" ixy="0.0" ixz="0.0" iyy="8.53e-06" iyz="-1.06e-06" izz="1.77e-06" />
    </inertial>
  </link>
  <joint name="arm_1_gripper_fr3_finger_joint1" type="prismatic">
    <parent link="arm_1_gripper_fr3_hand" />
    <child link="arm_1_gripper_fr3_leftfinger" />
    <origin rpy="0 0 0" xyz="0 0 0.0584" />
    <axis xyz="0 1 0" />
    <limit effort="100" lower="0.0" upper="0.04" velocity="0.2" />
    <dynamics damping="0.3" />
  </joint>
  <joint name="arm_1_gripper_fr3_finger_joint2" type="prismatic">
    <parent link="arm_1_gripper_fr3_hand" />
    <child link="arm_1_gripper_fr3_rightfinger" />
    <origin rpy="0 0 3.141592653589793" xyz="0 0 0.0584" />
    <axis xyz="0 1 0" />
    <limit effort="100" lower="0.0" upper="0.04" velocity="0.2" />
    <dynamics damping="0.3" />
  </joint>
  <link name="body_link">
    </link>
  <joint name="body_joint" type="fixed">
    <parent link="lift_0_mount_rotated_link" />
    <child link="body_link" />
    <origin rpy="1.5708 0.0 1.5708" xyz="-0.1109 0.0 -1.1663" />
  </joint>
  <link name="cover_link">
    </link>
  <joint name="cover_joint" type="fixed">
    <parent link="chassis_link" />
    <child link="cover_link" />
    <origin rpy="1.5708 0.0 1.5708" xyz="0.0 0.0 0.0" />
  </joint>
  <link name="mounting_plate_link">
    </link>
  <joint name="mounting_plate_joint" type="fixed">
    <parent link="chassis_link" />
    <child link="mounting_plate_link" />
    <origin rpy="1.5708 0.0 1.5708" xyz="0.0 0.0 0.0" />
  </joint>
  <link name="neck_1">
    <inertial>
      <mass value="0.5" />
      <inertia ixx="0.001" ixy="0.0" ixz="0.0" iyy="0.001" iyz="0.0" izz="0.001" />
    </inertial>
  </link>
  <link name="neck_2">
    <inertial>
      <mass value="0.5" />
      <inertia ixx="0.001" ixy="0.0" ixz="0.0" iyy="0.001" iyz="0.0" izz="0.001" />
    </inertial>
  </link>
  <link name="head">
    <inertial>
      <mass value="2.5" />
      <inertia ixx="0.001" ixy="0.0" ixz="0.0" iyy="0.001" iyz="0.0" izz="0.001" />
    </inertial>
  </link>
  <joint name="head_fixed_joint" type="fixed">
    <parent link="lift_0_mount_rotated_link" />
    <child link="neck_1" />
  </joint>
  <joint name="head_pan_joint" type="revolute">
    <origin rpy="0.0 0.0 0.0" xyz="0.0279 0.0 0.0119" />
    <parent link="neck_1" />
    <child link="neck_2" />
    <axis xyz="0 0 1" />
    <limit effort="30" lower="-1.5707" upper="1.5707" velocity="1.5707" />
  </joint>
  <joint name="head_tilt_joint" type="revolute">
    <origin rpy="0.0 0.0 0.0" xyz="0.0 -0.034 0.1521" />
    <parent link="neck_2" />
    <child link="head" />
    <axis xyz="0 -1 0" />
    <limit effort="30" lower="-0.7853" upper="0.7853" velocity="1.5707" />
  </joint>
  <ros2_control name="garmi" type="system">
    <hardware>
      <plugin>/MultiverseHWInterface</plugin>
      <param name="world_name">world</param>
      <param name="length_unit">m</param>
      <param name="angle_unit">rad</param>
      <param name="mass_unit">kg</param>
      <param name="time_unit">s</param>
      <param name="handedness">rhs</param>
      <param name="host">tcp://127.0.0.1</param>
      <param name="server_port">7000</param>
      <param name="client_port">7600</param>
    </hardware>
    <joint name="front_left_wheel_joint">
      <state_interface name="position">
        <param name="initial_value">0.0</param>
      </state_interface>
      <state_interface name="velocity" />
    </joint>
    <joint name="front_right_wheel_joint">
      <state_interface name="position">
        <param name="initial_value">0.0</param>
      </state_interface>
      <state_interface name="velocity" />
    </joint>
    <joint name="rear_left_wheel_joint">
      <state_interface name="position">
        <param name="initial_value">0.0</param>
      </state_interface>
      <state_interface name="velocity" />
    </joint>
    <joint name="rear_right_wheel_joint">
      <state_interface name="position">
        <param name="initial_value">0.0</param>
      </state_interface>
      <state_interface name="velocity" />
    </joint>
    <joint name="head_pan_joint">
      <state_interface name="position">
        <param name="initial_value">0.0</param>
      </state_interface>
      <state_interface name="velocity" />
      <param name="actuator">head_pan_actuator</param>
      <command_interface name="position">
        <param name="min">-1.5707</param>
        <param name="max">1.5707</param>
        <param name="initial_value">0.0</param>
      </command_interface>
      <command_interface name="velocity">
        <param name="min">-1000.0</param>
        <param name="max">1000.0</param>
      </command_interface>
      <command_interface name="effort">
        <param name="min">-1000.0</param>
        <param name="max">1000.0</param>
      </command_interface>
    </joint>
    <joint name="head_tilt_joint">
      <state_interface name="position">
        <param name="initial_value">0.0</param>
      </state_interface>
      <state_interface name="velocity" />
      <param name="actuator">head_tilt_actuator</param>
      <command_interface name="position">
        <param name="min">-0.7853</param>
        <param name="max">0.7853</param>
        <param name="initial_value">0.0</param>
      </command_interface>
      <command_interface name="velocity">
        <param name="min">-1000.0</param>
        <param name="max">1000.0</param>
      </command_interface>
      <command_interface name="effort">
        <param name="min">-1000.0</param>
        <param name="max">1000.0</param>
      </command_interface>
    </joint>
    <joint name="lift_0_lower_joint">
      <state_interface name="position">
        <param name="initial_value">0.0</param>
      </state_interface>
      <state_interface name="velocity" />
      <param name="actuator">lift_0</param>
      <command_interface name="position">
        <param name="min">0</param>
        <param name="max">0.4</param>
        <param name="initial_value">0</param>
      </command_interface>
      <command_interface name="velocity">
        <param name="min">-1000.0</param>
        <param name="max">1000.0</param>
      </command_interface>
      <command_interface name="effort">
        <param name="min">-1000.0</param>
        <param name="max">1000.0</param>
      </command_interface>
    </joint>
    <joint name="lift_0_upper_joint">
      <state_interface name="position">
        <param name="initial_value">0.0</param>
      </state_interface>
      <state_interface name="velocity" />
    </joint>
    <joint name="arm_0_fr3_joint1">
      <state_interface name="position">
        <param name="initial_value">0</param>
      </state_interface>
      <state_interface name="velocity" />
      <param name="actuator">arm_0_actuator1</param>
      <command_interface name="position">
        <param name="min">-2.9007</param>
        <param name="max">2.9007</param>
        <param name="initial_value">0</param>
      </command_interface>
      <command_interface name="velocity">
        <param name="min">-1000.0</param>
        <param name="max">1000.0</param>
      </command_interface>
      <command_interface name="effort">
        <param name="min">-1000.0</param>
        <param name="max">1000.0</param>
      </command_interface>
    </joint>
    <joint name="arm_0_fr3_joint2">
      <state_interface name="position">
        <param name="initial_value">0</param>
      </state_interface>
      <state_interface name="velocity" />
      <param name="actuator">arm_0_actuator2</param>
      <command_interface name="position">
        <param name="min">-1.8361</param>
        <param name="max">1.8361</param>
        <param name="initial_value">0</param>
      </command_interface>
      <command_interface name="velocity">
        <param name="min">-1000.0</param>
        <param name="max">1000.0</param>
      </command_interface>
      <command_interface name="effort">
        <param name="min">-1000.0</param>
        <param name="max">1000.0</param>
      </command_interface>
    </joint>
    <joint name="arm_0_fr3_joint3">
      <state_interface name="position">
        <param name="initial_value">0</param>
      </state_interface>
      <state_interface name="velocity" />
      <param name="actuator">arm_0_actuator3</param>
      <command_interface name="position">
        <param name="min">-2.9007</param>
        <param name="max">2.9007</param>
        <param name="initial_value">0</param>
      </command_interface>
      <command_interface name="velocity">
        <param name="min">-1000.0</param>
        <param name="max">1000.0</param>
      </command_interface>
      <command_interface name="effort">
        <param name="min">-1000.0</param>
        <param name="max">1000.0</param>
      </command_interface>
    </joint>
    <joint name="arm_0_fr3_joint4">
      <state_interface name="position">
        <param name="initial_value">0</param>
      </state_interface>
      <state_interface name="velocity" />
      <param name="actuator">arm_0_actuator4</param>
      <command_interface name="position">
        <param name="min">-3.077</param>
        <param name="max">-0.1169</param>
        <param name="initial_value">0</param>
      </command_interface>
      <command_interface name="velocity">
        <param name="min">-1000.0</param>
        <param name="max">1000.0</param>
      </command_interface>
      <command_interface name="effort">
        <param name="min">-1000.0</param>
        <param name="max">1000.0</param>
      </command_interface>
    </joint>
    <joint name="arm_0_fr3_joint5">
      <state_interface name="position">
        <param name="initial_value">0</param>
      </state_interface>
      <state_interface name="velocity" />
      <param name="actuator">arm_0_actuator5</param>
      <command_interface name="position">
        <param name="min">-2.8763</param>
        <param name="max">2.8763</param>
        <param name="initial_value">0</param>
      </command_interface>
      <command_interface name="velocity">
        <param name="min">-1000.0</param>
        <param name="max">1000.0</param>
      </command_interface>
      <command_interface name="effort">
        <param name="min">-1000.0</param>
        <param name="max">1000.0</param>
      </command_interface>
    </joint>
    <joint name="arm_0_fr3_joint6">
      <state_interface name="position">
        <param name="initial_value">0</param>
      </state_interface>
      <state_interface name="velocity" />
      <param name="actuator">arm_0_actuator6</param>
      <command_interface name="position">
        <param name="min">0.4398</param>
        <param name="max">4.6216</param>
        <param name="initial_value">0</param>
      </command_interface>
      <command_interface name="velocity">
        <param name="min">-1000.0</param>
        <param name="max">1000.0</param>
      </command_interface>
      <command_interface name="effort">
        <param name="min">-1000.0</param>
        <param name="max">1000.0</param>
      </command_interface>
    </joint>
    <joint name="arm_0_fr3_joint7">
      <state_interface name="position">
        <param name="initial_value">0</param>
      </state_interface>
      <state_interface name="velocity" />
      <param name="actuator">arm_0_actuator7</param>
      <command_interface name="position">
        <param name="min">-3.0508</param>
        <param name="max">3.0508</param>
        <param name="initial_value">0</param>
      </command_interface>
      <command_interface name="velocity">
        <param name="min">-1000.0</param>
        <param name="max">1000.0</param>
      </command_interface>
      <command_interface name="effort">
        <param name="min">-1000.0</param>
        <param name="max">1000.0</param>
      </command_interface>
    </joint>
    <joint name="arm_1_fr3_joint1">
      <state_interface name="position">
        <param name="initial_value">0</param>
      </state_interface>
      <state_interface name="velocity" />
      <param name="actuator">arm_1_actuator1</param>
      <command_interface name="position">
        <param name="min">-2.9007</param>
        <param name="max">2.9007</param>
        <param name="initial_value">0</param>
      </command_interface>
      <command_interface name="velocity">
        <param name="min">-1000.0</param>
        <param name="max">1000.0</param>
      </command_interface>
      <command_interface name="effort">
        <param name="min">-1000.0</param>
        <param name="max">1000.0</param>
      </command_interface>
    </joint>
    <joint name="arm_1_fr3_joint2">
      <state_interface name="position">
        <param name="initial_value">0</param>
      </state_interface>
      <state_interface name="velocity" />
      <param name="actuator">arm_1_actuator2</param>
      <command_interface name="position">
        <param name="min">-1.8361</param>
        <param name="max">1.8361</param>
        <param name="initial_value">0</param>
      </command_interface>
      <command_interface name="velocity">
        <param name="min">-1000.0</param>
        <param name="max">1000.0</param>
      </command_interface>
      <command_interface name="effort">
        <param name="min">-1000.0</param>
        <param name="max">1000.0</param>
      </command_interface>
    </joint>
    <joint name="arm_1_fr3_joint3">
      <state_interface name="position">
        <param name="initial_value">0</param>
      </state_interface>
      <state_interface name="velocity" />
      <param name="actuator">arm_1_actuator3</param>
      <command_interface name="position">
        <param name="min">-2.9007</param>
        <param name="max">2.9007</param>
        <param name="initial_value">0</param>
      </command_interface>
      <command_interface name="velocity">
        <param name="min">-1000.0</param>
        <param name="max">1000.0</param>
      </command_interface>
      <command_interface name="effort">
        <param name="min">-1000.0</param>
        <param name="max">1000.0</param>
      </command_interface>
    </joint>
    <joint name="arm_1_fr3_joint4">
      <state_interface name="position">
        <param name="initial_value">0</param>
      </state_interface>
      <state_interface name="velocity" />
      <param name="actuator">arm_1_actuator4</param>
      <command_interface name="position">
        <param name="min">-3.077</param>
        <param name="max">-0.1169</param>
        <param name="initial_value">0</param>
      </command_interface>
      <command_interface name="velocity">
        <param name="min">-1000.0</param>
        <param name="max">1000.0</param>
      </command_interface>
      <command_interface name="effort">
        <param name="min">-1000.0</param>
        <param name="max">1000.0</param>
      </command_interface>
    </joint>
    <joint name="arm_1_fr3_joint5">
      <state_interface name="position">
        <param name="initial_value">0</param>
      </state_interface>
      <state_interface name="velocity" />
      <param name="actuator">arm_1_actuator5</param>
      <command_interface name="position">
        <param name="min">-2.8763</param>
        <param name="max">2.8763</param>
        <param name="initial_value">0</param>
      </command_interface>
      <command_interface name="velocity">
        <param name="min">-1000.0</param>
        <param name="max">1000.0</param>
      </command_interface>
      <command_interface name="effort">
        <param name="min">-1000.0</param>
        <param name="max">1000.0</param>
      </command_interface>
    </joint>
    <joint name="arm_1_fr3_joint6">
      <state_interface name="position">
        <param name="initial_value">0</param>
      </state_interface>
      <state_interface name="velocity" />
      <param name="actuator">arm_1_actuator6</param>
      <command_interface name="position">
        <param name="min">0.4398</param>
        <param name="max">4.6216</param>
        <param name="initial_value">0</param>
      </command_interface>
      <command_interface name="velocity">
        <param name="min">-1000.0</param>
        <param name="max">1000.0</param>
      </command_interface>
      <command_interface name="effort">
        <param name="min">-1000.0</param>
        <param name="max">1000.0</param>
      </command_interface>
    </joint>
    <joint name="arm_1_fr3_joint7">
      <state_interface name="position">
        <param name="initial_value">0</param>
      </state_interface>
      <state_interface name="velocity" />
      <param name="actuator">arm_1_actuator7</param>
      <command_interface name="position">
        <param name="min">-3.0508</param>
        <param name="max">3.0508</param>
        <param name="initial_value">0</param>
      </command_interface>
      <command_interface name="velocity">
        <param name="min">-1000.0</param>
        <param name="max">1000.0</param>
      </command_interface>
      <command_interface name="effort">
        <param name="min">-1000.0</param>
        <param name="max">1000.0</param>
      </command_interface>
    </joint>
    <joint name="arm_0_gripper_fr3_finger_joint1">
      <state_interface name="position">
        <param name="initial_value">0.0</param>
      </state_interface>
      <state_interface name="velocity" />
    </joint>
    <joint name="arm_0_gripper_fr3_finger_joint2">
      <state_interface name="position">
        <param name="initial_value">0.0</param>
      </state_interface>
      <state_interface name="velocity" />
    </joint>
    <joint name="arm_1_gripper_fr3_finger_joint1">
      <state_interface name="position">
        <param name="initial_value">0.0</param>
      </state_interface>
      <state_interface name="velocity" />
    </joint>
    <joint name="arm_1_gripper_fr3_finger_joint2">
      <state_interface name="position">
        <param name="initial_value">0.0</param>
      </state_interface>
      <state_interface name="velocity" />
    </joint>
  </ros2_control>
</robot>